Workbook

Sheet Sheet3
A3: Row Labels | B3: Sum of TOTAL REVISADO | C3: Sum of VALOR AJUSTADO
A4: 3 | B4: 6238.23 | C4: 2585
A5: 4 | B5: 3827.97 | C5: 2157.78
A6: Grand Total | B6: 10066.2 | C6: 4742.78

Sheet Sheet2
A1: # Factura | B1: Company | C1: Period - Invoice | D1: Month | E1: Year | F1: Period Limena | G1: User actual | H1: # Mobil | I1: Page Number | J1: Monthly Charges | K1: Usage and Purchase Charges | L1: Equipment Charges | M1: Surcharges and Other Charges and Credits | N1: Taxes, Governmental Surcharges and Fees | O1: Third-Party Charges (includes Tax) | P1: Total Charges | Q1: CTA | R1: Director | S1: Manager | T1: DEP | U1: iphone o ipad | V1: migrado | W1: COBRO ACORDADO
A2: 287289507033X06092025 | B2: AT&T | C2: JUNIO | D2: 6 | E2: 2025 | F2: 9 | G2: Group 7 | H2: 629-257-4960 | I2: 5 | J2: - | K2: $40.00 | L2: - | M2: - | N2: - | P2: 40 | Q2: 60311003 | R2: 04 | S2: 0401 | T2: 040101 | U2: =IFERROR(+VLOOKUP(H2,'DISPOSITIVOS ACTIVOS'!B:D,3,FALSE),"IPHONE") -> no aplica | V2: =IFERROR(+VLOOKUP(H2,'[1]Migracion feb25 Ver to ATT'!$B:$G,6,FALSE), "NO MIGRADO") -> NO MIGRADO | W2: 25
A3: 287289507033X06092025 | B3: AT&T | C3: JUNIO | D3: 6 | E3: 2025 | F3: 9 | G3: BACKUP INTERNET 1 | H3: 629-257-4960 | I3: 7 | J3: - | K3: $15.00 | L3: - | M3: $3.75 | N3: - | P3: 18.75 | Q3: 60311003 | R3: 04 | S3: 0401 | T3: 040101 | U3: =IFERROR(+VLOOKUP(H3,'DISPOSITIVOS ACTIVOS'!B:D,3,FALSE),"IPHONE") -> no aplica | V3: =IFERROR(+VLOOKUP(H3,'[1]Migracion feb25 Ver to ATT'!$B:$G,6,FALSE), "NO MIGRADO") -> NO MIGRADO | W3: 25
A4: 287289507033X06092025 | B4: AT&T | C4: JUNIO | D4: 6 | E4: 2025 | F4: 9 | G4: Group 8 | H4: 629-258-0227 | I4: 5 | J4: - | K4: $40.00 | L4: - | M4: - | N4: - | P4: 40 | Q4: 60311003 | R4: 04 | S4: 0401 | T4: 040101 | U4: =IFERROR(+VLOOKUP(H4,'DISPOSITIVOS ACTIVOS'!B:D,3,FALSE),"IPHONE") -> no aplica | V4: =IFERROR(+VLOOKUP(H4,'[1]Migracion feb25 Ver to ATT'!$B:$G,6,FALSE), "NO MIGRADO") -> NO MIGRADO | W4: 25
A5: 287289507033X06092025 | B5: AT&T | C5: JUNIO | D5: 6 | E5: 2025 | F5: 9 | G5: BACKUP INTERNET 2 | H5: 629-258-0227 | I5: 9 | J5: - | K5: $15.00 | L5: - | M5: $3.75 | N5: - | P5: 18.75 | Q5: 60311003 | R5: 04 | S5: 0401 | T5: 040101 | U5: =IFERROR(+VLOOKUP(H5,'DISPOSITIVOS ACTIVOS'!B:D,3,FALSE),"IPHONE") -> no aplica | V5: =IFERROR(+VLOOKUP(H5,'[1]Migracion feb25 Ver to ATT'!$B:$G,6,FALSE), "NO MIGRADO") -> NO MIGRADO | W5: 25
A6: 287289507033X06092025 | B6: AT&T | C6: JUNIO | D6: 6 | E6: 2025 | F6: 9 | G6: JOSE MAITE SA | H6: 205-527-8021 | I6: 11 | J6: $0.00 | K6: $25.00 | L6: $5.00 | M6: $4.54 | N6: $5.83 | P6: 40.37 | Q6: 60311005 | R6: 04 | S6: 0401 | T6: 040105 | U6: =IFERROR(+VLOOKUP(H6,'DISPOSITIVOS ACTIVOS'!B:D,3,FALSE),"IPHONE") -> Iphone | V6: =IFERROR(+VLOOKUP(H6,'[1]Migracion feb25 Ver to ATT'!$B:$G,6,FALSE), "NO MIGRADO") -> NO MIGRADO | W6: 25
A7: 287289507033X06092025 | B7: AT&T | C7: JUNIO | D7: 6 | E7: 2025 | F7: 9 | G7: ROSMARY SILVA | H7: 205-529-6296 | I7: 13 | J7: $0.00 | K7: $50.00 | L7: - | M7: $4.87 | N7: $5.37 | P7: 60.24 | Q7: 60311005 | R7: 04 | S7: 0401 | T7: 040105 | U7: =IFERROR(+VLOOKUP(H7,'DISPOSITIVOS ACTIVOS'!B:D,3,FALSE),"IPHONE") -> Iphone | V7: =IFERROR(+VLOOKUP(H7,'[1]Migracion feb25 Ver to ATT'!$B:$G,6,FALSE), "NO MIGRADO") -> Iphone | W7: 15
A8: 287289507033X06092025 | B8: AT&T | C8: JUNIO | D8: 6 | E8: 2025 | F8: 9 | G8: JESUS GUERRERO | H8: 205-767-8090 | I8: 15 | J8: $0.00 | K8: $50.00 | L8: - | M8: $4.87 | N8: $5.37 | P8: 60.24 | Q8: 60311005 | R8: 04 | S8: 0401 | T8: 040105 | U8: =IFERROR(+VLOOKUP(H8,'DISPOSITIVOS ACTIVOS'!B:D,3,FALSE),"IPHONE") -> Iphone | V8: =IFERROR(+VLOOKUP(H8,'[1]Migracion feb25 Ver to ATT'!$B:$G,6,FALSE), "NO MIGRADO") -> Iphone | W8: 15
A9: 287289507033X06092025 | B9: AT&T | C9: JUNIO | D9: 6 | E9: 2025 | F9: 9 | G9: DANIEL FLORES IPAD SA | H9: 256-631-4188 | I9: 17 | J9: - | K9: $15.00 | L9: - | M9: $3.75 | N9: - | P9: 18.75 | Q9: 60311003 | R9: 04 | S9: 0401 | T9: 040105 | U9: =IFERROR(+VLOOKUP(H9,'DISPOSITIVOS ACTIVOS'!B:D,3,FALSE),"IPHONE") -> Ipad | V9: =IFERROR(+VLOOKUP(H9,'[1]Migracion feb25 Ver to ATT'!$B:$G,6,FALSE), "NO MIGRADO") -> NO MIGRADO | W9: 15
A10: 287289507033X06092025 | B10: AT&T | C10: JUNIO | D10: 6 | E10: 2025 | F10: 9 | G10: DANIEL FLORES SA | H10: 256-724-1530 | I10: 19 | J10: $0.00 | K10: $25.00 | L10: $10.99 | M10: $4.54 | N10: $5.83 | P10: 46.36 | Q10: 60311005 | R10: 04 | S10: 0401 | T10: 040105 | U10: =IFERROR(+VLOOKUP(H10,'DISPOSITIVOS ACTIVOS'!B:D,3,FALSE),"IPHONE") -> Iphone | V10: =IFERROR(+VLOOKUP(H10,'[1]Migracion feb25 Ver to ATT'!$B:$G,6,FALSE), "NO MIGRADO") -> NO MIGRADO | W10: 25
A11: 287289507033X06092025 | B11: AT&T | C11: JUNIO | D11: 6 | E11: 2025 | F11: 9 | G11: AMALIA BENOCMO | H11: 270-779-9642 | I11: 21 | J11: - | K11: $50.00 | L11: - | M11: $5.58 | N11: $1.33 | P11: 56.91 | Q11: 60311005 | R11: 04 | S11: 0401 | T11: 040101 | U11: =IFERROR(+VLOOKUP(H11,'DISPOSITIVOS ACTIVOS'!B:D,3,FALSE),"IPHONE") -> 0 | V11: =IFERROR(+VLOOKUP(H11,'[1]Migracion feb25 Ver to ATT'!$B:$G,6,FALSE), "NO MIGRADO") -> NO MIGRADO | W11: 25
A12: 287289507033X06092025 | B12: AT&T | C12: JUNIO | D12: 6 | E12: 2025 | F12: 9 | G12: ERNESTO PAUMIER - N... | H12: 283-229-3007 | I12: 23 | J12: $21.00 | K12: $50.00 | L12: - | M12: $5.30 | N12: $2.87 | P12: 79.17 | Q12: 60311005 | R12: 03 | S12: 0303 | T12: 030302 | U12: =IFERROR(+VLOOKUP(H12,'DISPOSITIVOS ACTIVOS'!B:D,3,FALSE),"IPHONE") -> Samsung | V12: =IFERROR(+VLOOKUP(H12,'[1]Migracion feb25 Ver to ATT'!$B:$G,6,FALSE), "NO MIGRADO") -> NO MIGRADO | W12: 25
A13: 287289507033X06092025 | B13: AT&T | C13: JUNIO | D13: 6 | E13: 2025 | F13: 9 | G13: WILLIAM HARRIS - NO... | H13: 283-229-3008 | I13: 25 | J13: $21.00 | K13: $50.00 | L13: - | M13: $5.30 | N13: $2.87 | P13: 79.17 | Q13: 60311005 | R13: 03 | S13: 0303 | T13: 030302 | U13: =IFERROR(+VLOOKUP(H13,'DISPOSITIVOS ACTIVOS'!B:D,3,FALSE),"IPHONE") -> Samsung | V13: =IFERROR(+VLOOKUP(H13,'[1]Migracion feb25 Ver to ATT'!$B:$G,6,FALSE), "NO MIGRADO") -> NO MIGRADO | W13: 25
... A20: 287289507033X06092025 | B20: AT&T | C20: JUNIO | D20: 6 | E20: 2025 | F20: 9 | G20: KAREN ORELLANA | H20: 470-330-9757 | I20: 39 | J20: $12.50 | K20: $25.00 | L20: - | M20: $1.47 | N20: $3.71 | P20: 42.68 | Q20: 60311005 | R20: 04 | S20: 0401 | T20: 040101 | U20: =IFERROR(+VLOOKUP(H20,'DISPOSITIVOS ACTIVOS'!B:D,3,FALSE),"IPHONE") -> IPHONE | V20: =IFERROR(+VLOOKUP(H20,'[1]Migracion feb25 Ver to ATT'!$B:$G,6,FALSE), "NO MIGRADO") -> NO MIGRADO | W20: 25
A21: 287289507033X06092025 | B21: AT&T | C21: JUNIO | D21: 6 | E21: 2025 | F21: 9 | G21: DANIEL GARCIA | H21: 470-609-0538 | I21: 41 | J21: $0.00 | K21: $25.00 | L21: - | M21: $4.54 | N21: $2.14 | P21: 31.68 | Q21: 10145003 | U21: =IFERROR(+VLOOKUP(H21,'DISPOSITIVOS ACTIVOS'!B:D,3,FALSE),"IPHONE") -> no aplica | V21: =IFERROR(+VLOOKUP(H21,'[1]Migracion feb25 Ver to ATT'!$B:$G,6,FALSE), "NO MIGRADO") -> NO MIGRADO | W21: 25
A22: 287289507033X06092025 | B22: AT&T | C22: JUNIO | D22: 6 | E22: 2025 | F22: 9 | G22: OSCAR BARRAGAN | H22: 470-609-0570 | I22: 43 | J22: $0.00 | K22: $25.00 | L22: - | M22: $4.54 | N22: $2.14 | P22: 31.68 | Q22: 10145003 | U22: =IFERROR(+VLOOKUP(H22,'DISPOSITIVOS ACTIVOS'!B:D,3,FALSE),"IPHONE") -> no aplica | V22: =IFERROR(+VLOOKUP(H22,'[1]Migracion feb25 Ver to ATT'!$B:$G,6,FALSE), "NO MIGRADO") -> NO MIGRADO | W22: 25
A23: 287289507033X06092025 | B23: AT&T | C23: JUNIO | D23: 6 | E23: 2025 | F23: 9 | G23: ISRAEL LOPEZ | H23: 470-737-8596 | I23: 45 | J23: - | K23: - | L23: - | M23: - | N23: - | P23: 0 | Q23: 60311005 | R23: 03 | S23: 0302 | T23: 030201 | U23: =IFERROR(+VLOOKUP(H23,'DISPOSITIVOS ACTIVOS'!B:D,3,FALSE),"IPHONE") -> IPHONE | V23: =IFERROR(+VLOOKUP(H23,'[1]Migracion feb25 Ver to ATT'!$B:$G,6,FALSE), "NO MIGRADO") -> NO MIGRADO | W23: 25
A24: 287289507033X06092025 | B24: AT&T | C24: JUNIO | D24: 6 | E24: 2025 | F24: 9 | G24: SALES ARKANSAS | H24: 501-773-3738 | I24: 47 | J24: - | K24: $15.00 | L24: - | M24: $3.75 | N24: - | P24: 18.75 | Q24: 60311003 | R24: 04 | S24: 0401 | T24: 040103 | U24: =IFERROR(+VLOOKUP(H24,'DISPOSITIVOS ACTIVOS'!B:D,3,FALSE),"IPHONE") -> Ipad | V24: =IFERROR(+VLOOKUP(H24,'[1]Migracion feb25 Ver to ATT'!$B:$G,6,FALSE), "NO MIGRADO") -> NO MIGRADO | W24: 15
A25: 287289507033X06092025 | B25: AT&T | C25: JUNIO | D25: 6 | E25: 2025 | F25: 9 | G25: ARTURO VILLAVICENCIO | H25: 501-773-3763 | I25: 49 | J25: $0.00 | K25: $50.00 | L25: - | M25: $4.87 | N25: $5.37 | P25: 60.24 | Q25: 60311005 | R25: 04 | S25: 0401 | T25: 040103 | U25: =IFERROR(+VLOOKUP(H25,'DISPOSITIVOS ACTIVOS'!B:D,3,FALSE),"IPHONE") -> Iphone | V25: =IFERROR(+VLOOKUP(H25,'[1]Migracion feb25 Ver to ATT'!$B:$G,6,FALSE), "NO MIGRADO") -> Iphone | W25: 15
A26: 287289507033X06092025 | B26: AT&T | C26: JUNIO | D26: 6 | E26: 2025 | F26: 9 | G26: DILVER GARCIA | H26: 502-341-1558 | I26: 51 | J26: -$8.34 | K26: $50.00 | L26: - | M26: $4.75 | N26: $4.25 | P26: 50.66 | Q26: 60311005 | R26: 04 | S26: 0401 | T26: 040101 | U26: =IFERROR(+VLOOKUP(H26,'DISPOSITIVOS ACTIVOS'!B:D,3,FALSE),"IPHONE") -> 0 | V26: =IFERROR(+VLOOKUP(H26,'[1]Migracion feb25 Ver to ATT'!$B:$G,6,FALSE), "NO MIGRADO") -> Galaxy | W26: 15
A27: 287289507033X06092025 | B27: AT&T | C27: JUNIO | D27: 6 | E27: 2025 | F27: 9 | G27: JAVIER MOJICA LG | H27: 502-558-5770 | I27: 53 | J27: $1.66 | K27: $50.00 | L27: - | M27: $4.88 | N27: $2.36 | P27: 58.9 | Q27: 60311005 | R27: 03 | S27: 0303 | T27: 030301 | U27: =IFERROR(+VLOOKUP(H27,'DISPOSITIVOS ACTIVOS'!B:D,3,FALSE),"IPHONE") -> Galaxy | V27: =IFERROR(+VLOOKUP(H27,'[1]Migracion feb25 Ver to ATT'!$B:$G,6,FALSE), "NO MIGRADO") -> Galaxy | W27: 15
A28: 287289507033X06092025 | B28: AT&T | C28: JUNIO | D28: 6 | E28: 2025 | F28: 9 | G28: CLAUDIA ARMES | H28: 502-974-3915 | I28: 55 | J28: $0.00 | K28: $50.00 | L28: - | M28: $4.87 | N28: $5.37 | P28: 60.24 | Q28: 60311005 | R28: 04 | S28: 0401 | T28: 040102 | U28: =IFERROR(+VLOOKUP(H28,'DISPOSITIVOS ACTIVOS'!B:D,3,FALSE),"IPHONE") -> Iphone | V28: =IFERROR(+VLOOKUP(H28,'[1]Migracion feb25 Ver to ATT'!$B:$G,6,FALSE), "NO MIGRADO") -> Iphone | W28: 15
A29: 287289507033X06092025 | B29: AT&T | C29: JUNIO | D29: 6 | E29: 2025 | F29: 9 | G29: IRIS CORDERO | H29: 513-675-0865 | I29: 57 | J29: $0.00 | K29: $50.00 | L29: - | M29: $4.87 | N29: $5.37 | P29: 60.24 | Q29: 60311005 | R29: 04 | S29: 0401 | T29: 040102 | U29: =IFERROR(+VLOOKUP(H29,'DISPOSITIVOS ACTIVOS'!B:D,3,FALSE),"IPHONE") -> Iphone | V29: =IFERROR(+VLOOKUP(H29,'[1]Migracion feb25 Ver to ATT'!$B:$G,6,FALSE), "NO MIGRADO") -> Iphone | W29: 15
A30: 287289507033X06092025 | B30: AT&T | C30: JUNIO | D30: 6 | E30: 2025 | F30: 9 | G30: CINCINNATI LIMENA | H30: 513-720-1147 | I30: 59 | J30: $0.00 | K30: $25.00 | L30: $5.00 | M30: $4.61 | N30: $5.10 | P30: 39.71 | Q30: 60311005 | R30: 04 | S30: 0402 | T30: 040202 | U30: =IFERROR(+VLOOKUP(H30,'DISPOSITIVOS ACTIVOS'!B:D,3,FALSE),"IPHONE") -> Iphone | V30: =IFERROR(+VLOOKUP(H30,'[1]Migracion feb25 Ver to ATT'!$B:$G,6,FALSE), "NO MIGRADO") -> NO MIGRADO | W30: 25
A31: 287289507033X06092025 | B31: AT&T | C31: JUNIO | D31: 6 | E31: 2025 | F31: 9 | G31: ROSMARY LACRUZ | H31: 601-910-8492 | I31: 61 | J31: $0.00 | K31: $50.00 | L31: - | M31: $4.87 | N31: $5.37 | P31: 60.24 | Q31: 60311005 | R31: 04 | S31: 0401 | T31: 040103 | U31: =IFERROR(+VLOOKUP(H31,'DISPOSITIVOS ACTIVOS'!B:D,3,FALSE),"IPHONE") -> Iphone | V31: =IFERROR(+VLOOKUP(H31,'[1]Migracion feb25 Ver to ATT'!$B:$G,6,FALSE), "NO MIGRADO") -> Iphone | W31: 15
A32: 287289507033X06092025 | B32: AT&T | C32: JUNIO | D32: 6 | E32: 2025 | F32: 9 | G32: OSMAN CABRERA | H32: 615-207-2464 | I32: 63 | J32: $0.00 | K32: $50.00 | L32: - | M32: $4.87 | N32: $5.37 | P32: 60.24 | Q32: 60311005 | R32: 04 | S32: 0401 | T32: 040101 | U32: =IFERROR(+VLOOKUP(H32,'DISPOSITIVOS ACTIVOS'!B:D,3,FALSE),"IPHONE") -> Iphone | V32: =IFERROR(+VLOOKUP(H32,'[1]Migracion feb25 Ver to ATT'!$B:$G,6,FALSE), "NO MIGRADO") -> Iphone | W32: 15
A33: 287289507033X06092025 | B33: AT&T | C33: JUNIO | D33: 6 | E33: 2025 | F33: 9 | G33: SIMON CASTELLANO | H33: 615-299-3640 | I33: 65 | J33: - | K33: $50.00 | L33: - | M33: $4.86 | N33: $2.48 | P33: 57.34 | Q33: 60311005 | R33: 03 | S33: 0303 | T33: 030308 | U33: =IFERROR(+VLOOKUP(H33,'DISPOSITIVOS ACTIVOS'!B:D,3,FALSE),"IPHONE") -> Galaxy | V33: =IFERROR(+VLOOKUP(H33,'[1]Migracion feb25 Ver to ATT'!$B:$G,6,FALSE), "NO MIGRADO") -> Galaxy | W33: 15
A34: 287289507033X06092025 | B34: AT&T | C34: JUNIO | D34: 6 | E34: 2025 | F34: 9 | G34: EDGAR FERNANDEZ LQ | H34: 615-299-3641 | I34: 67 | J34: $0.00 | K34: $25.00 | L34: - | M34: $4.54 | N34: $7.20 | P34: 36.74 | Q34: 60311005 | R34: 03 | S34: 0303 | T34: 030301 | U34: =IFERROR(+VLOOKUP(H34,'DISPOSITIVOS ACTIVOS'!B:D,3,FALSE),"IPHONE") -> Motorola | V34: =IFERROR(+VLOOKUP(H34,'[1]Migracion feb25 Ver to ATT'!$B:$G,6,FALSE), "NO MIGRADO") -> NO MIGRADO | W34: 25
A35: 287289507033X06092025 | B35: AT&T | C35: JUNIO | D35: 6 | E35: 2025 | F35: 9 | G35: IPAD SALES | H35: 615-305-1999 | I35: 69 | J35: - | K35: $10.00 | L35: - | M35: - | N35: - | P35: 10 | Q35: 60311003 | R35: 04 | S35: 0401 | T35: 040101 | U35: =IFERROR(+VLOOKUP(H35,'DISPOSITIVOS ACTIVOS'!B:D,3,FALSE),"IPHONE") -> IPHONE | V35: =IFERROR(+VLOOKUP(H35,'[1]Migracion feb25 Ver to ATT'!$B:$G,6,FALSE), "NO MIGRADO") -> NO MIGRADO | W35: 25
A36: 287289507033X06092025 | B36: AT&T | C36: JUNIO | D36: 6 | E36: 2025 | F36: 9 | G36: ALBERT CARDOZO | H36: 615-310-9970 | I36: 71 | J36: - | K36: $15.00 | L36: - | M36: $3.75 | N36: - | P36: 18.75 | Q36: 10145005 | U36: =IFERROR(+VLOOKUP(H36,'DISPOSITIVOS ACTIVOS'!B:D,3,FALSE),"IPHONE") -> Ipad | V36: =IFERROR(+VLOOKUP(H36,'[1]Migracion feb25 Ver to ATT'!$B:$G,6,FALSE), "NO MIGRADO") -> Ipad | W36: 15
A37: 287289507033X06092025 | B37: AT&T | C37: JUNIO | D37: 6 | E37: 2025 | F37: 9 | G37: HR LIMENA | H37: 615-316-8577 | I37: 73 | J37: $0.00 | K37: $25.00 | L37: $25.00 | M37: $4.54 | N37: $7.20 | P37: 61.74 | Q37: 60311005 | R37: 09 | S37: 0900 | T37: 090000 | U37: =IFERROR(+VLOOKUP(H37,'DISPOSITIVOS ACTIVOS'!B:D,3,FALSE),"IPHONE") -> Iphone | V37: =IFERROR(+VLOOKUP(H37,'[1]Migracion feb25 Ver to ATT'!$B:$G,6,FALSE), "NO MIGRADO") -> NO MIGRADO | W37: 25
A38: 287289507033X06092025 | B38: AT&T | C38: JUNIO | D38: 6 | E38: 2025 | F38: 9 | G38: DAVID CONDE WH | H38: 615-337-4949 | I38: 75 | J38: $0.00 | K38: $50.00 | L38: - | M38: $4.87 | N38: $5.37 | P38: 60.24 | Q38: 60311005 | R38: 03 | S38: 0302 | T38: 030201 | U38: =IFERROR(+VLOOKUP(H38,'DISPOSITIVOS ACTIVOS'!B:D,3,FALSE),"IPHONE") -> Galaxy | V38: =IFERROR(+VLOOKUP(H38,'[1]Migracion feb25 Ver to ATT'!$B:$G,6,FALSE), "NO MIGRADO") -> NO MIGRADO | W38: 25
A39: 287289507033X06092025 | B39: AT&T | C39: JUNIO | D39: 6 | E39: 2025 | F39: 9 | G39: HENRY ESQUIVEL | H39: 615-390-4624 | I39: 77 | J39: $0.00 | K39: $50.00 | L39: - | M39: $4.87 | N39: $5.37 | P39: 60.24 | Q39: 60311005 | R39: 03 | S39: 0302 | T39: 030201 | U39: =IFERROR(+VLOOKUP(H39,'DISPOSITIVOS ACTIVOS'!B:D,3,FALSE),"IPHONE") -> Iphone | V39: =IFERROR(+VLOOKUP(H39,'[1]Migracion feb25 Ver to ATT'!$B:$G,6,FALSE), "NO MIGRADO") -> Iphone | W39: 15
A40: 287289507033X06092025 | B40: AT&T | C40: JUNIO | D40: 6 | E40: 2025 | F40: 9 | G40: MERARI VILLATORO | H40: 615-403-8760 | I40: 79 | J40: $0.44 | K40: $25.00 | L40: $38.89 | M40: $6.74 | N40: $7.65 | P40: 78.72 | Q40: 60311005 | R40: 02 | S40: 0200 | T40: 020000 | U40: =IFERROR(+VLOOKUP(H40,'DISPOSITIVOS ACTIVOS'!B:D,3,FALSE),"IPHONE") -> Iphone | V40: =IFERROR(+VLOOKUP(H40,'[1]Migracion feb25 Ver to ATT'!$B:$G,6,FALSE), "NO MIGRADO") -> NO MIGRADO | W40: 25
A41: 287289507033X06092025 | B41: AT&T | C41: JUNIO | D41: 6 | E41: 2025 | F41: 9 | G41: JESSICA BARAJAS LA | H41: 615-417-0015 | I41: 81 | J41: $0.00 | K41: $25.00 | L41: - | M41: $4.54 | N41: $7.20 | P41: 36.74 | Q41: 60311005 | R41: 04 | S41: 0401 | T41: 040102 | U41: =IFERROR(+VLOOKUP(H41,'DISPOSITIVOS ACTIVOS'!B:D,3,FALSE),"IPHONE") -> Iphone | V41: =IFERROR(+VLOOKUP(H41,'[1]Migracion feb25 Ver to ATT'!$B:$G,6,FALSE), "NO MIGRADO") -> NO MIGRADO | W41: 25
A42: 287289507033X06092025 | B42: AT&T | C42: JUNIO | D42: 6 | E42: 2025 | F42: 9 | G42: NICOLAS FINANZAS | H42: 615-417-9594 | I42: 83 | J42: $0.00 | K42: $25.00 | L42: - | M42: $4.54 | N42: $7.20 | P42: 36.74 | Q42: 60311005 | R42: 06 | S42: 0600 | T42: 060000 | U42: =IFERROR(+VLOOKUP(H42,'DISPOSITIVOS ACTIVOS'!B:D,3,FALSE),"IPHONE") -> Iphone | V42: =IFERROR(+VLOOKUP(H42,'[1]Migracion feb25 Ver to ATT'!$B:$G,6,FALSE), "NO MIGRADO") -> NO MIGRADO | W42: 25
A43: 287289507033X06092025 | B43: AT&T | C43: JUNIO | D43: 6 | E43: 2025 | F43: 9 | G43: ZEDRICK PATINO | H43: 615-426-4622 | I43: 85 | J43: $0.00 | K43: $25.00 | L43: - | M43: $4.54 | N43: $7.20 | P43: 36.74 | Q43: 60311005 | R43: 04 | S43: 0402 | T43: 040201 | U43: =IFERROR(+VLOOKUP(H43,'DISPOSITIVOS ACTIVOS'!B:D,3,FALSE),"IPHONE") -> Iphone | V43: =IFERROR(+VLOOKUP(H43,'[1]Migracion feb25 Ver to ATT'!$B:$G,6,FALSE), "NO MIGRADO") -> NO MIGRADO | W43: 25
A44: 287289507033X06092025 | B44: AT&T | C44: JUNIO | D44: 6 | E44: 2025 | F44: 9 | G44: DANNY CABANZO | H44: 615-456-2536 | I44: 87 | J44: $0.00 | K44: $50.00 | L44: - | M44: $4.87 | N44: $5.37 | P44: 60.24 | Q44: 60311005 | R44: 04 | S44: 0401 | T44: 040101 | U44: =IFERROR(+VLOOKUP(H44,'DISPOSITIVOS ACTIVOS'!B:D,3,FALSE),"IPHONE") -> Iphone | V44: =IFERROR(+VLOOKUP(H44,'[1]Migracion feb25 Ver to ATT'!$B:$G,6,FALSE), "NO MIGRADO") -> Iphone | W44: 15
A45: 287289507033X06092025 | B45: AT&T | C45: JUNIO | D45: 6 | E45: 2025 | F45: 9 | G45: MONICA AYALA | H45: 615-476-5992 | I45: 89 | J45: $12.50 | K45: $25.00 | L45: - | M45: $1.47 | N45: $3.71 | P45: 42.68 | Q45: 60311005 | R45: 04 | S45: 0402 | T45: 040201 | U45: =IFERROR(+VLOOKUP(H45,'DISPOSITIVOS ACTIVOS'!B:D,3,FALSE),"IPHONE") -> IPHONE | V45: =IFERROR(+VLOOKUP(H45,'[1]Migracion feb25 Ver to ATT'!$B:$G,6,FALSE), "NO MIGRADO") -> NO MIGRADO | W45: 25
A46: 287289507033X06092025 | B46: AT&T | C46: JUNIO | D46: 6 | E46: 2025 | F46: 9 | G46: MERARI TWOLINE | H46: 615-477-6490 | I46: 91 | J46: $0.00 | K46: $25.00 | L46: $30.56 | M46: $4.54 | N46: $7.20 | P46: 67.3 | Q46: 60311005 | R46: 02 | S46: 0200 | T46: 020000 | U46: =IFERROR(+VLOOKUP(H46,'DISPOSITIVOS ACTIVOS'!B:D,3,FALSE),"IPHONE") -> Iphone | V46: =IFERROR(+VLOOKUP(H46,'[1]Migracion feb25 Ver to ATT'!$B:$G,6,FALSE), "NO MIGRADO") -> NO MIGRADO | W46: 25
...

Sheet Sheet4
A1: Proveedor | B1: (All)
A3: Row Labels | B3: Sum of TOTAL REVISADO | C3: Sum of VALOR AJUSTADO
A4: 3 | B4: 6238.23 | C4: 2585
A5: 4 | B5: 3827.97 | C5: 2157.78
A6: 5 | B6: 5246.05 | C6: 2780
A7: Grand Total | B7: 15312.25 | C7: 7522.78

Sheet FACTURAS
A1: Proveedor | B1: Year | C1: Month | D1: Number | E1: USER | F1: asa | G1: Activity | H1: Monthly charges | I1: Equipment | J1: Company | K1: Government | L1: total | M1: TOTAL REVISADO | N1: DISPOSITIVO | O1: USER REAL | P1: CECO | Q1: MIGRADO | R1: VALOR AJUSTADO
A2: AT&T | B2: 25 | C2: 3 | D2: 629-345-1381 | E2: IPHONE 14 | F2: 13 | G2: -4.17 | H2: 45 | I2: 5.99 | J2: 4.36 | K2: 2.08 | L2: 53.26 | M2: =+L2 -> 53.26 | N2: =+VLOOKUP(D2,'DISPOSITIVOS ACTIVOS'!B:D,3,FALSE) -> Iphone | O2: =+VLOOKUP(D2,'DISPOSITIVOS ACTIVOS'!B:G,6,FALSE) -> RIVERO, LUIS MARIANO | P2: =+VLOOKUP(D2,'DISPOSITIVOS ACTIVOS'!$B$1:$H$299,7,FALSE) -> SALES CENTRAL | Q2: =IFERROR(+VLOOKUP(D2,'[1]Migracion feb25 Ver to ATT'!$B:$B,1,FALSE), "NO") -> NO | R2: =+IF(Q2="NO",25,15) -> 25
A3: AT&T | B3: 25 | C3: 3 | D3: 629-345-1642 | E3: IPHONE 14 | F3: 15 | G3: -4.17 | H3: 45 | I3: 5.99 | J3: 4.36 | K3: 2.08 | L3: 53.26 | M3: =+L3 -> 53.26 | N3: =+VLOOKUP(D3,'DISPOSITIVOS ACTIVOS'!B:D,3,FALSE) -> Iphone | O3: =+VLOOKUP(D3,'DISPOSITIVOS ACTIVOS'!B:G,6,FALSE) -> CALDERON, PILAR ESTRADA | P3: =+VLOOKUP(D3,'DISPOSITIVOS ACTIVOS'!$B$1:$H$299,7,FALSE) -> MERCHANDISER SOUTH | Q3: =IFERROR(+VLOOKUP(D3,'[1]Migracion feb25 Ver to ATT'!$B:$B,1,FALSE), "NO") -> NO | R3: =+IF(Q3="NO",25,15) -> 25
A4: AT&T | B4: 25 | C4: 3 | D4: 629-345-1645 | E4: RADDY GARCIA SA | F4: 17 | G4: -4.17 | H4: 45 | I4: 5.99 | J4: 4.36 | K4: 2.08 | L4: 53.26 | M4: =+L4 -> 53.26 | N4: =+VLOOKUP(D4,'DISPOSITIVOS ACTIVOS'!B:D,3,FALSE) -> Iphone | O4: =+VLOOKUP(D4,'DISPOSITIVOS ACTIVOS'!B:G,6,FALSE) -> GARCIA, RADDY | P4: =+VLOOKUP(D4,'DISPOSITIVOS ACTIVOS'!$B$1:$H$299,7,FALSE) -> SALES NORTH | Q4: =IFERROR(+VLOOKUP(D4,'[1]Migracion feb25 Ver to ATT'!$B:$B,1,FALSE), "NO") -> NO | R4: =+IF(Q4="NO",25,15) -> 25
A5: AT&T | B5: 25 | C5: 3 | D5: 678-477-4654 | E5: IPAD SALES | F5: 19 | G5: -5 | H5: 20 | I5: - | J5: 3.75 | K5: - | L5: 18.75 | M5: =+L5 -> 18.75 | N5: =+VLOOKUP(D5,'DISPOSITIVOS ACTIVOS'!B:D,3,FALSE) -> no aplica | O5: =+VLOOKUP(D5,'DISPOSITIVOS ACTIVOS'!B:G,6,FALSE) -> IPAD SALES | P5: =+VLOOKUP(D5,'DISPOSITIVOS ACTIVOS'!$B$1:$H$299,7,FALSE) -> ATLANTA | Q5: =IFERROR(+VLOOKUP(D5,'[1]Migracion feb25 Ver to ATT'!$B:$B,1,FALSE), "NO") -> NO | R5: =+IF(Q5="NO",25,15) -> 25
A6: AT&T | B6: 25 | C6: 3 | D6: 678-925-1523 | E6: IPAD SALES | F6: 21 | G6: -5 | H6: 20 | I6: - | J6: 3.75 | K6: - | L6: 18.75 | M6: =+L6 -> 18.75 | N6: =+VLOOKUP(D6,'DISPOSITIVOS ACTIVOS'!B:D,3,FALSE) -> no aplica | O6: =+VLOOKUP(D6,'DISPOSITIVOS ACTIVOS'!B:G,6,FALSE) -> IPAD SALES | P6: =+VLOOKUP(D6,'DISPOSITIVOS ACTIVOS'!$B$1:$H$299,7,FALSE) -> ATLANTA | Q6: =IFERROR(+VLOOKUP(D6,'[1]Migracion feb25 Ver to ATT'!$B:$B,1,FALSE), "NO") -> NO | R6: =+IF(Q6="NO",25,15) -> 25
A7: AT&T | B7: 25 | C7: 3 | D7: 678-925-6858 | E7: IPAD SALES | F7: 23 | G7: -5 | H7: 20 | I7: - | J7: 3.75 | K7: - | L7: 18.75 | M7: =+L7 -> 18.75 | N7: =+VLOOKUP(D7,'DISPOSITIVOS ACTIVOS'!B:D,3,FALSE) -> no aplica | O7: =+VLOOKUP(D7,'DISPOSITIVOS ACTIVOS'!B:G,6,FALSE) -> IPAD SALES | P7: =+VLOOKUP(D7,'DISPOSITIVOS ACTIVOS'!$B$1:$H$299,7,FALSE) -> ATLANTA | Q7: =IFERROR(+VLOOKUP(D7,'[1]Migracion feb25 Ver to ATT'!$B:$B,1,FALSE), "NO") -> NO | R7: =+IF(Q7="NO",25,15) -> 25
A8: AT&T | B8: 25 | C8: 3 | D8: 901-464-6471 | E8: HELEN MADRIGAL | F8: 25 | G8: - | H8: 50 | I8: -0.79 | J8: 4.4 | K8: 2.12 | L8: 55.73 | M8: =+L8 -> 55.73 | N8: =+VLOOKUP(D8,'DISPOSITIVOS ACTIVOS'!B:D,3,FALSE) -> Iphone | O8: =+VLOOKUP(D8,'DISPOSITIVOS ACTIVOS'!B:G,6,FALSE) -> MADRIGAL GARCIA, HELEN C | P8: =+VLOOKUP(D8,'DISPOSITIVOS ACTIVOS'!$B$1:$H$299,7,FALSE) -> SALES NORTH | Q8: =IFERROR(+VLOOKUP(D8,'[1]Migracion feb25 Ver to ATT'!$B:$B,1,FALSE), "NO") -> NO | R8: =+IF(Q8="NO",25,15) -> 25
A9: AT&T | B9: 25 | C9: 3 | D9: 615-474-6646 | E9: JOHAN MADRIZ | F9: 27 | G9: - | H9: 20 | I9: - | J9: 3.75 | K9: - | L9: 23.75 | M9: 88.75 | N9: CANCELADO | O9: CANCELADO | P9: =+VLOOKUP(D9,'DISPOSITIVOS ACTIVOS'!$B$1:$H$299,7,FALSE) -> #N/A | Q9: =IFERROR(+VLOOKUP(D9,'[1]Migracion feb25 Ver to ATT'!$B:$B,1,FALSE), "NO") -> NO | R9: =+IF(Q9="NO",25,15) -> 25
A10: AT&T | B10: 25 | C10: 3 | D10: 629-257-4960 | E10: BACKUP INTERNET 1 | F10: 29 | G10: - | H10: 20 | I10: - | J10: 3.75 | K10: - | L10: 23.75 | M10: 63.75 | N10: Samsung | O10: =+VLOOKUP(D10,'DISPOSITIVOS ACTIVOS'!B:G,6,FALSE) -> Backup Internet | P10: =+VLOOKUP(D10,'DISPOSITIVOS ACTIVOS'!$B$1:$H$299,7,FALSE) -> SALES CENTRAL | Q10: =IFERROR(+VLOOKUP(D10,'[1]Migracion feb25 Ver to ATT'!$B:$B,1,FALSE), "NO") -> NO | R10: =+IF(Q10="NO",25,15) -> 25
A11: AT&T | B11: 25 | C11: 3 | D11: 629-258-0227 | E11: BACKUP INTERNET 2 | F11: 31 | G11: - | H11: 20 | I11: - | J11: 3.75 | K11: - | L11: 23.75 | M11: 63.75 | N11: Samsung | O11: =+VLOOKUP(D11,'DISPOSITIVOS ACTIVOS'!B:G,6,FALSE) -> Backup Internet | P11: =+VLOOKUP(D11,'DISPOSITIVOS ACTIVOS'!$B$1:$H$299,7,FALSE) -> SALES CENTRAL | Q11: =IFERROR(+VLOOKUP(D11,'[1]Migracion feb25 Ver to ATT'!$B:$B,1,FALSE), "NO") -> NO | R11: =+IF(Q11="NO",25,15) -> 25
A12: AT&T | B12: 25 | C12: 3 | D12: 615-945-4365 | E12: IVAN TELLO IPAD | F12: 33 | G12: - | H12: - | I12: - | J12: 3.75 | K12: - | L12: 3.75 | M12: 23.75 | N12: =+VLOOKUP(D12,'DISPOSITIVOS ACTIVOS'!B:D,3,FALSE) -> Ipad | O12: =+VLOOKUP(D12,'DISPOSITIVOS ACTIVOS'!B:G,6,FALSE) -> TELLO, IVAN E | P12: =+VLOOKUP(D12,'DISPOSITIVOS ACTIVOS'!$B$1:$H$299,7,FALSE) -> SALES CENTRAL | Q12: =IFERROR(+VLOOKUP(D12,'[1]Migracion feb25 Ver to ATT'!$B:$B,1,FALSE), "NO") -> NO | R12: =+IF(Q12="NO",25,15) -> 25
A13: AT&T | B13: 25 | C13: 3 | D13: 615-944-5380 | E13: LEONARDO PALENCIA I... | F13: 35 | G13: - | H13: - | I13: - | J13: 3.75 | K13: - | L13: 3.75 | M13: 23.75 | N13: =+VLOOKUP(D13,'DISPOSITIVOS ACTIVOS'!B:D,3,FALSE) -> Ipad | O13: =+VLOOKUP(D13,'DISPOSITIVOS ACTIVOS'!B:G,6,FALSE) -> PALENCIA RODRIGUEZ, LEONARDO R | P13: =+VLOOKUP(D13,'DISPOSITIVOS ACTIVOS'!$B$1:$H$299,7,FALSE) -> SALES CENTRAL | Q13: =IFERROR(+VLOOKUP(D13,'[1]Migracion feb25 Ver to ATT'!$B:$B,1,FALSE), "NO") -> NO | R13: =+IF(Q13="NO",25,15) -> 25
A14: AT&T | B14: 25 | C14: 3 | D14: 615-585-1725 | E14: SALES DSD IPAD | F14: 37 | G14: - | H14: - | I14: - | J14: 3.75 | K14: - | L14: 3.75 | M14: 23.75 | N14: CANCELADO | O14: CANCELADO | P14: =+VLOOKUP(D14,'DISPOSITIVOS ACTIVOS'!$B$1:$H$299,7,FALSE) -> #N/A | Q14: =IFERROR(+VLOOKUP(D14,'[1]Migracion feb25 Ver to ATT'!$B:$B,1,FALSE), "NO") -> NO | R14: =+IF(Q14="NO",25,15) -> 25
A15: AT&T | B15: 25 | C15: 3 | D15: 256-631-4188 | E15: DANIEL FLORES IPAD SA | F15: 39 | G15: 4.12 | H15: - | I15: - | J15: 3.75 | K15: - | L15: 7.87 | M15: 27.87 | N15: =+VLOOKUP(D15,'DISPOSITIVOS ACTIVOS'!B:D,3,FALSE) -> Ipad | O15: =+VLOOKUP(D15,'DISPOSITIVOS ACTIVOS'!B:G,6,FALSE) -> FLORES, JOSE DANIEL | P15: =+VLOOKUP(D15,'DISPOSITIVOS ACTIVOS'!$B$1:$H$299,7,FALSE) -> SALES SOUTH | Q15: =IFERROR(+VLOOKUP(D15,'[1]Migracion feb25 Ver to ATT'!$B:$B,1,FALSE), "NO") -> NO | R15: =+IF(Q15="NO",25,15) -> 25
A16: AT&T | B16: 25 | C16: 3 | D16: 629-345-1182 | E16: ROSMARY LA CRUZ IPA... | F16: 41 | G16: - | H16: - | I16: - | J16: 3.75 | K16: - | L16: 3.75 | M16: 23.75 | N16: =+VLOOKUP(D16,'DISPOSITIVOS ACTIVOS'!B:D,3,FALSE) -> Ipad | O16: =+VLOOKUP(D16,'DISPOSITIVOS ACTIVOS'!B:G,6,FALSE) -> LACRUZ, ROSMARY | P16: =+VLOOKUP(D16,'DISPOSITIVOS ACTIVOS'!$B$1:$H$299,7,FALSE) -> SALES WEST | Q16: =IFERROR(+VLOOKUP(D16,'[1]Migracion feb25 Ver to ATT'!$B:$B,1,FALSE), "NO") -> NO | R16: =+IF(Q16="NO",25,15) -> 25
A17: AT&T | B17: 25 | C17: 3 | D17: 901-467-5902 | E17: HELEN MADRIGAL IPAD SA | F17: 43 | G17: - | H17: - | I17: - | J17: 3.75 | K17: - | L17: 3.75 | M17: 23.75 | N17: =+VLOOKUP(D17,'DISPOSITIVOS ACTIVOS'!B:D,3,FALSE) -> Ipad | O17: =+VLOOKUP(D17,'DISPOSITIVOS ACTIVOS'!B:G,6,FALSE) -> MADRIGAL GARCIA, HELEN C | P17: =+VLOOKUP(D17,'DISPOSITIVOS ACTIVOS'!$B$1:$H$299,7,FALSE) -> SALES NORTH | Q17: =IFERROR(+VLOOKUP(D17,'[1]Migracion feb25 Ver to ATT'!$B:$B,1,FALSE), "NO") -> NO | R17: =+IF(Q17="NO",25,15) -> 25
A18: AT&T | B18: 25 | C18: 3 | D18: 629-345-1728 | E18: IPAD DISTRIBUIDORA ... | F18: 45 | G18: - | H18: - | I18: 12.78 | J18: 3.75 | K18: - | L18: 16.53 | M18: 36.53 | N18: =+VLOOKUP(D18,'DISPOSITIVOS ACTIVOS'!B:D,3,FALSE) -> Ipad | O18: =+VLOOKUP(D18,'DISPOSITIVOS ACTIVOS'!B:G,6,FALSE) -> GARCIA, RADDY | P18: =+VLOOKUP(D18,'DISPOSITIVOS ACTIVOS'!$B$1:$H$299,7,FALSE) -> SALES NORTH | Q18: =IFERROR(+VLOOKUP(D18,'[1]Migracion feb25 Ver to ATT'!$B:$B,1,FALSE), "NO") -> NO | R18: =+IF(Q18="NO",25,15) -> 25
A19: AT&T | B19: 25 | C19: 3 | D19: 629-345-1705 | E19: IPAD DISTRIBUIDORA ... | F19: 47 | G19: - | H19: - | I19: 12.78 | J19: 3.75 | K19: - | L19: 16.53 | M19: 36.53 | N19: =+VLOOKUP(D19,'DISPOSITIVOS ACTIVOS'!B:D,3,FALSE) -> Ipad | O19: =+VLOOKUP(D19,'DISPOSITIVOS ACTIVOS'!B:G,6,FALSE) -> CALDERON, PILAR ESTRADA | P19: =+VLOOKUP(D19,'DISPOSITIVOS ACTIVOS'!$B$1:$H$299,7,FALSE) -> MERCHANDISER SOUTH | Q19: =IFERROR(+VLOOKUP(D19,'[1]Migracion feb25 Ver to ATT'!$B:$B,1,FALSE), "NO") -> NO | R19: =+IF(Q19="NO",25,15) -> 25
A20: AT&T | B20: 25 | C20: 3 | D20: 629-345-1574 | E20: IPAD DISTRIBUIDORA ... | F20: 49 | G20: - | H20: - | I20: 12.78 | J20: 3.75 | K20: - | L20: 16.53 | M20: 36.53 | N20: =+VLOOKUP(D20,'DISPOSITIVOS ACTIVOS'!B:D,3,FALSE) -> Ipad | O20: =+VLOOKUP(D20,'DISPOSITIVOS ACTIVOS'!B:G,6,FALSE) -> RIVERO, LUIS MARIANO | P20: =+VLOOKUP(D20,'DISPOSITIVOS ACTIVOS'!$B$1:$H$299,7,FALSE) -> SALES CENTRAL | Q20: =IFERROR(+VLOOKUP(D20,'[1]Migracion feb25 Ver to ATT'!$B:$B,1,FALSE), "NO") -> NO | R20: =+IF(Q20="NO",25,15) -> 25
A21: AT&T | B21: 25 | C21: 3 | D21: 629-729-3294 | E21: IPAD EDILIA SHINE | F21: 51 | G21: - | H21: - | I21: - | J21: 3.75 | K21: - | L21: 3.75 | M21: 23.75 | N21: =+VLOOKUP(D21,'DISPOSITIVOS ACTIVOS'!B:D,3,FALSE) -> Ipad | O21: =+VLOOKUP(D21,'DISPOSITIVOS ACTIVOS'!B:G,6,FALSE) -> SHINE, EDILIA D | P21: =+VLOOKUP(D21,'DISPOSITIVOS ACTIVOS'!$B$1:$H$299,7,FALSE) -> SALES NORTH | Q21: =IFERROR(+VLOOKUP(D21,'[1]Migracion feb25 Ver to ATT'!$B:$B,1,FALSE), "NO") -> NO | R21: =+IF(Q21="NO",25,15) -> 25
A22: AT&T | B22: 25 | C22: 3 | D22: 629-729-3287 | E22: IPAD RAFAEL CHANCHA... | F22: 53 | G22: - | H22: - | I22: - | J22: 3.75 | K22: - | L22: 3.75 | M22: 23.75 | N22: =+VLOOKUP(D22,'DISPOSITIVOS ACTIVOS'!B:D,3,FALSE) -> Ipad | O22: =+VLOOKUP(D22,'DISPOSITIVOS ACTIVOS'!B:G,6,FALSE) -> CHANCHAMIRE, RAFAEL A | P22: =+VLOOKUP(D22,'DISPOSITIVOS ACTIVOS'!$B$1:$H$299,7,FALSE) -> SALES WEST | Q22: =IFERROR(+VLOOKUP(D22,'[1]Migracion feb25 Ver to ATT'!$B:$B,1,FALSE), "NO") -> NO | R22: =+IF(Q22="NO",25,15) -> 25
A23: AT&T | B23: 25 | C23: 3 | D23: 205-527-8021 | E23: JOSE MAITE SA | F23: 55 | G23: 4.11 | H23: 50 | I23: 5 | J23: 4.87 | K23: 2.9 | L23: 66.88 | M23: =+L23 -> 66.88 | N23: =+VLOOKUP(D23,'DISPOSITIVOS ACTIVOS'!B:D,3,FALSE) -> Iphone | O23: =+VLOOKUP(D23,'DISPOSITIVOS ACTIVOS'!B:G,6,FALSE) -> MAITA, JOSE | P23: =+VLOOKUP(D23,'DISPOSITIVOS ACTIVOS'!$B$1:$H$299,7,FALSE) -> SALES SOUTH | Q23: =IFERROR(+VLOOKUP(D23,'[1]Migracion feb25 Ver to ATT'!$B:$B,1,FALSE), "NO") -> NO | R23: =+IF(Q23="NO",25,15) -> 25
A24: AT&T | B24: 25 | C24: 3 | D24: 205-529-6296 | E24: ROSMARY SILVA | F24: 57 | G24: -30.88 | H24: 50 | I24: - | J24: 4.23 | K24: 1.92 | L24: 25.27 | M24: =+L24 -> 25.27 | N24: =+VLOOKUP(D24,'DISPOSITIVOS ACTIVOS'!B:D,3,FALSE) -> Iphone | O24: =+VLOOKUP(D24,'DISPOSITIVOS ACTIVOS'!B:G,6,FALSE) -> SILVA R, ROSMARY JOSE | P24: =+VLOOKUP(D24,'DISPOSITIVOS ACTIVOS'!$B$1:$H$299,7,FALSE) -> SALES SOUTH | Q24: =IFERROR(+VLOOKUP(D24,'[1]Migracion feb25 Ver to ATT'!$B:$B,1,FALSE), "NO") -> 205-529-6296 | R24: =+IF(Q24="NO",25,15) -> 15
A25: AT&T | B25: 25 | C25: 3 | D25: 205-767-8090 | E25: JESUS GUERRERO | F25: 59 | G25: -35 | H25: 50 | I25: - | J25: 4.23 | K25: 1.92 | L25: 21.15 | M25: =+L25 -> 21.15 | N25: =+VLOOKUP(D25,'DISPOSITIVOS ACTIVOS'!B:D,3,FALSE) -> Iphone | O25: =+VLOOKUP(D25,'DISPOSITIVOS ACTIVOS'!B:G,6,FALSE) -> GUERRERO, JESUS | P25: =+VLOOKUP(D25,'DISPOSITIVOS ACTIVOS'!$B$1:$H$299,7,FALSE) -> SALES SOUTH | Q25: =IFERROR(+VLOOKUP(D25,'[1]Migracion feb25 Ver to ATT'!$B:$B,1,FALSE), "NO") -> 205-767-8090 | R25: =+IF(Q25="NO",25,15) -> 15
A26: AT&T | B26: 25 | C26: 3 | D26: 256-724-1530 | E26: DANIEL FLORES SA | F26: 61 | G26: 4.12 | H26: 50 | I26: 10.99 | J26: 4.87 | K26: 2.9 | L26: 72.88 | M26: =+L26 -> 72.88 | N26: =+VLOOKUP(D26,'DISPOSITIVOS ACTIVOS'!B:D,3,FALSE) -> Iphone | O26: =+VLOOKUP(D26,'DISPOSITIVOS ACTIVOS'!B:G,6,FALSE) -> FLORES, JOSE DANIEL | P26: =+VLOOKUP(D26,'DISPOSITIVOS ACTIVOS'!$B$1:$H$299,7,FALSE) -> SALES SOUTH | Q26: =IFERROR(+VLOOKUP(D26,'[1]Migracion feb25 Ver to ATT'!$B:$B,1,FALSE), "NO") -> NO | R26: =+IF(Q26="NO",25,15) -> 25
A27: AT&T | B27: 25 | C27: 3 | D27: 314-309-4058 | E27: YESENIA LOPEZ | F27: 63 | G27: - | H27: 50 | I27: 5 | J27: 4.87 | K27: 2.57 | L27: 62.44 | M27: =+L27 -> 62.44 | N27: =+VLOOKUP(D27,'DISPOSITIVOS ACTIVOS'!B:D,3,FALSE) -> Iphone | O27: =+VLOOKUP(D27,'DISPOSITIVOS ACTIVOS'!B:G,6,FALSE) -> LOPEZ, YESENIA | P27: =+VLOOKUP(D27,'DISPOSITIVOS ACTIVOS'!$B$1:$H$299,7,FALSE) -> SALES WEST | Q27: =IFERROR(+VLOOKUP(D27,'[1]Migracion feb25 Ver to ATT'!$B:$B,1,FALSE), "NO") -> NO | R27: =+IF(Q27="NO",25,15) -> 25
A28: AT&T | B28: 25 | C28: 3 | D28: 314-580-3315 | E28: VICTOR CAICEDO | F28: 65 | G28: -30.88 | H28: 50 | I28: - | J28: 4.23 | K28: 1.92 | L28: 25.27 | M28: =+L28 -> 25.27 | N28: =+VLOOKUP(D28,'DISPOSITIVOS ACTIVOS'!B:D,3,FALSE) -> Iphone | O28: =+VLOOKUP(D28,'DISPOSITIVOS ACTIVOS'!B:G,6,FALSE) -> CAICEDO, VICTOR M | P28: =+VLOOKUP(D28,'DISPOSITIVOS ACTIVOS'!$B$1:$H$299,7,FALSE) -> SALES WEST | Q28: =IFERROR(+VLOOKUP(D28,'[1]Migracion feb25 Ver to ATT'!$B:$B,1,FALSE), "NO") -> 314-580-3315 | R28: =+IF(Q28="NO",25,15) -> 15
A29: AT&T | B29: 25 | C29: 3 | D29: 317-500-7156 | E29: NAYELY SORIANO | F29: 67 | G29: -30.88 | H29: 50 | I29: - | J29: 4.23 | K29: 1.92 | L29: 25.27 | M29: =+L29 -> 25.27 | N29: =+VLOOKUP(D29,'DISPOSITIVOS ACTIVOS'!B:D,3,FALSE) -> Iphone | O29: =+VLOOKUP(D29,'DISPOSITIVOS ACTIVOS'!B:G,6,FALSE) -> SORIANO, NAYELY | P29: =+VLOOKUP(D29,'DISPOSITIVOS ACTIVOS'!$B$1:$H$299,7,FALSE) -> SALES NORTH | Q29: =IFERROR(+VLOOKUP(D29,'[1]Migracion feb25 Ver to ATT'!$B:$B,1,FALSE), "NO") -> 317-500-7156 | R29: =+IF(Q29="NO",25,15) -> 15
A30: AT&T | B30: 25 | C30: 3 | D30: 423-321-4014 | E30: JUAN CARLOS CORADO | F30: 69 | G30: -35 | H30: 50 | I30: - | J30: 4.23 | K30: 1.92 | L30: 21.15 | M30: =+L30 -> 21.15 | N30: =+VLOOKUP(D30,'DISPOSITIVOS ACTIVOS'!B:D,3,FALSE) -> Iphone | O30: =+VLOOKUP(D30,'DISPOSITIVOS ACTIVOS'!B:G,6,FALSE) -> CORADO, JUAN CARLOS | P30: =+VLOOKUP(D30,'DISPOSITIVOS ACTIVOS'!$B$1:$H$299,7,FALSE) -> SALES SOUTH | Q30: =IFERROR(+VLOOKUP(D30,'[1]Migracion feb25 Ver to ATT'!$B:$B,1,FALSE), "NO") -> 423-321-4014 | R30: =+IF(Q30="NO",25,15) -> 15
A31: AT&T | B31: 25 | C31: 3 | D31: 463-209-9259 | E31: EDILIA SSHINE SA | F31: 71 | G31: 4.12 | H31: 50 | I31: - | J31: 4.87 | K31: 2.57 | L31: 61.56 | M31: =+L31 -> 61.56 | N31: =+VLOOKUP(D31,'DISPOSITIVOS ACTIVOS'!B:D,3,FALSE) -> Iphone | O31: =+VLOOKUP(D31,'DISPOSITIVOS ACTIVOS'!B:G,6,FALSE) -> SHINE, EDILIA D | P31: =+VLOOKUP(D31,'DISPOSITIVOS ACTIVOS'!$B$1:$H$299,7,FALSE) -> SALES NORTH | Q31: =IFERROR(+VLOOKUP(D31,'[1]Migracion feb25 Ver to ATT'!$B:$B,1,FALSE), "NO") -> NO | R31: =+IF(Q31="NO",25,15) -> 25
A32: AT&T | B32: 25 | C32: 3 | D32: 463-867-7910 | E32: NEW INDY USER DISTR... | F32: 73 | G32: 4.12 | H32: 50 | I32: 5.99 | J32: 5.02 | K32: 1.78 | L32: 66.91 | M32: =+L32 -> 66.91 | N32: CANCELADO | O32: CANCELADO | P32: =+VLOOKUP(D32,'DISPOSITIVOS ACTIVOS'!$B$1:$H$299,7,FALSE) -> #N/A | Q32: =IFERROR(+VLOOKUP(D32,'[1]Migracion feb25 Ver to ATT'!$B:$B,1,FALSE), "NO") -> NO | R32: =+IF(Q32="NO",25,15) -> 25
A33: AT&T | B33: 25 | C33: 3 | D33: 470-330-9757 | E33: KAREN ORELLANA | F33: 75 | G33: - | H33: 50 | I33: - | J33: 4.87 | K33: 2.57 | L33: 57.44 | M33: =+L33 -> 57.44 | N33: CANCELADO | O33: CANCELADO | P33: =+VLOOKUP(D33,'DISPOSITIVOS ACTIVOS'!$B$1:$H$299,7,FALSE) -> #N/A | Q33: =IFERROR(+VLOOKUP(D33,'[1]Migracion feb25 Ver to ATT'!$B:$B,1,FALSE), "NO") -> NO | R33: =+IF(Q33="NO",25,15) -> 25
A34: AT&T | B34: 25 | C34: 3 | D34: 470-609-0538 | E34: DANIEL GARCIA | F34: 77 | G34: 4.12 | H34: 50 | I34: - | J34: 4.87 | K34: 2.39 | L34: 61.38 | M34: =+L34 -> 61.38 | N34: =+VLOOKUP(D34,'DISPOSITIVOS ACTIVOS'!B:D,3,FALSE) -> no aplica | O34: =+VLOOKUP(D34,'DISPOSITIVOS ACTIVOS'!B:G,6,FALSE) -> DANIEL GARCIA | P34: =+VLOOKUP(D34,'DISPOSITIVOS ACTIVOS'!$B$1:$H$299,7,FALSE) -> ATLANTA | Q34: =IFERROR(+VLOOKUP(D34,'[1]Migracion feb25 Ver to ATT'!$B:$B,1,FALSE), "NO") -> NO | R34: =+IF(Q34="NO",25,15) -> 25
A35: AT&T | B35: 25 | C35: 3 | D35: 470-609-0570 | E35: OSCAR BARRAGAN | F35: 79 | G35: 4.12 | H35: 50 | I35: - | J35: 4.87 | K35: 2.39 | L35: 61.38 | M35: =+L35 -> 61.38 | N35: =+VLOOKUP(D35,'DISPOSITIVOS ACTIVOS'!B:D,3,FALSE) -> no aplica | O35: =+VLOOKUP(D35,'DISPOSITIVOS ACTIVOS'!B:G,6,FALSE) -> OSCAR BARRAGAN | P35: =+VLOOKUP(D35,'DISPOSITIVOS ACTIVOS'!$B$1:$H$299,7,FALSE) -> ATLANTA | Q35: =IFERROR(+VLOOKUP(D35,'[1]Migracion feb25 Ver to ATT'!$B:$B,1,FALSE), "NO") -> NO | R35: =+IF(Q35="NO",25,15) -> 25
A36: AT&T | B36: 25 | C36: 3 | D36: 470-737-8596 | E36: ISRAEL LOPEZ | F36: 81 | G36: - | H36: 50 | I36: - | J36: 4.87 | K36: 2.57 | L36: 57.44 | M36: =+L36 -> 57.44 | N36: CANCELADO | O36: CANCELADO | P36: =+VLOOKUP(D36,'DISPOSITIVOS ACTIVOS'!$B$1:$H$299,7,FALSE) -> #N/A | Q36: =IFERROR(+VLOOKUP(D36,'[1]Migracion feb25 Ver to ATT'!$B:$B,1,FALSE), "NO") -> NO | R36: =+IF(Q36="NO",25,15) -> 25
A37: AT&T | B37: 25 | C37: 3 | D37: 501-773-3738 | E37: SALES ARKANSAS | F37: 83 | G37: 4.11 | H37: 30 | I37: - | J37: 3.75 | K37: - | L37: 37.86 | M37: =+L37 -> 37.86 | N37: =+VLOOKUP(D37,'DISPOSITIVOS ACTIVOS'!B:D,3,FALSE) -> Ipad | O37: =+VLOOKUP(D37,'DISPOSITIVOS ACTIVOS'!B:G,6,FALSE) -> VILLAVICENCIO, ARTURO J | P37: =+VLOOKUP(D37,'DISPOSITIVOS ACTIVOS'!$B$1:$H$299,7,FALSE) -> SALES WEST | Q37: =IFERROR(+VLOOKUP(D37,'[1]Migracion feb25 Ver to ATT'!$B:$B,1,FALSE), "NO") -> NO | R37: =+IF(Q37="NO",25,15) -> 25
A38: AT&T | B38: 25 | C38: 3 | D38: 501-773-3763 | E38: ARTURO VILLAVICENCIO | F38: 85 | G38: -30.89 | H38: 50 | I38: - | J38: 4.23 | K38: 1.92 | L38: 25.26 | M38: =+L38 -> 25.26 | N38: =+VLOOKUP(D38,'DISPOSITIVOS ACTIVOS'!B:D,3,FALSE) -> Iphone | O38: =+VLOOKUP(D38,'DISPOSITIVOS ACTIVOS'!B:G,6,FALSE) -> VILLAVICENCIO, ARTURO J | P38: =+VLOOKUP(D38,'DISPOSITIVOS ACTIVOS'!$B$1:$H$299,7,FALSE) -> SALES WEST | Q38: =IFERROR(+VLOOKUP(D38,'[1]Migracion feb25 Ver to ATT'!$B:$B,1,FALSE), "NO") -> 501-773-3763 | R38: =+IF(Q38="NO",25,15) -> 15
A39: AT&T | B39: 25 | C39: 3 | D39: 502-341-1558 | E39: DILVER GARCIA | F39: 87 | G39: -16.67 | H39: 50 | I39: - | J39: 4.56 | K39: 0.97 | L39: 38.86 | M39: =+L39 -> 38.86 | N39: =+VLOOKUP(D39,'DISPOSITIVOS ACTIVOS'!B:D,3,FALSE) -> 0 | O39: =+VLOOKUP(D39,'DISPOSITIVOS ACTIVOS'!B:G,6,FALSE) -> Backup | P39: =+VLOOKUP(D39,'DISPOSITIVOS ACTIVOS'!$B$1:$H$299,7,FALSE) -> SALES CENTRAL | Q39: =IFERROR(+VLOOKUP(D39,'[1]Migracion feb25 Ver to ATT'!$B:$B,1,FALSE), "NO") -> 502-341-1558 | R39: =+IF(Q39="NO",25,15) -> 15
A40: AT&T | B40: 25 | C40: 3 | D40: 502-558-5770 | E40: JAVIER MOJICA LG | F40: 89 | G40: 12.84 | H40: 25 | I40: - | J40: 5.53 | K40: 3.23 | L40: 46.6 | M40: =+L40 -> 46.6 | N40: =+VLOOKUP(D40,'DISPOSITIVOS ACTIVOS'!B:D,3,FALSE) -> Galaxy | O40: =+VLOOKUP(D40,'DISPOSITIVOS ACTIVOS'!B:G,6,FALSE) -> MOJICA, FRANCISCO JAVIER | P40: =+VLOOKUP(D40,'DISPOSITIVOS ACTIVOS'!$B$1:$H$299,7,FALSE) -> LOGISTICS CENTRAL | Q40: =IFERROR(+VLOOKUP(D40,'[1]Migracion feb25 Ver to ATT'!$B:$B,1,FALSE), "NO") -> 502-558-5770 | R40: =+IF(Q40="NO",25,15) -> 15
...

Sheet DISPOSITIVOS ACTIVOS
A1: ID | B1: LINEA MOVIL | C1: Proveedor | D1: EQUIPMENT TYPE | E1: MODEL | F1: IMEI | G1: Usuario Asignado | H1: CECO | I1: LINEA | J1: LOCATION | K1: Estado | L1: Fecha de asignacion | M1: Fecha de ultima revision | N1: Condicion de equipo | O1: Comentarios | P1: Confirmation Letter
A2: 001 | B2: 615-708-0397 | C2: AT&T | D2: Iphone | E2: A2849 256GB Black Titanium | F2: 356964995021992 | G2: MADRIZ, JOHAN | H2: President | I2: Primera | J2: Nashville | K2: Activo | L2: 45658 | M2: 45717 | N2: Perfecto
A3: 002 | B3: 615-477-6490 | C3: AT&T | D3: Iphone | E3: A2848 256GB White Titanium | F3: 352917261435522 | G3: VILLATORO, MERARI | H3: VP | I3: Primera | J3: Nashville | K3: Activo | L3: 45658 | M3: 45717 | N3: Perfecto
A4: 003
A5: 004
A6: 005 | B6: 615-496-8278 | C6: AT&T | D6: Iphone | E6: iphone 16 PRO Max 512 GB Black Titanium | F6: 357205981304151 | G6: MADRIZ, JOHAN | H6: President | I6: Primera | J6: Nashville | K6: Activo | L6: 45658 | M6: 45717 | N6: Perfecto
A7: 006 | B7: 615-403-8760 | C7: AT&T | D7: Iphone | E7: iPhone 13 Pro Max A2484 256GB Alpine Green | F7: 356985725478830 | G7: VILLATORO, MERARI | H7: VP | I7: Primera | J7: Nashville | K7: Activo | L7: 45658 | M7: 45717 | N7: Perfecto
A8: 007 | B8: 615-417-9594 | C8: AT&T | D8: Iphone | E8: iPhone 13 Pro Max A2484 256GB Graphite | F8: 350566101441174 | G8: QUIJANO, NICOLAS | H8: CFO | I8: Primera | J8: Nashville | K8: Activo | L8: 45658 | M8: 45717 | N8: Perfecto | P8: Send
A9: 008 | B9: 615-691-3166 | C9: AT&T | D9: Iphone | E9: iPhone 13 Pro Max A2484 256GB Gold | F9: 356796480675498 | G9: QUIJANO, NICOLAS | H9: CFO | I9: Primera | J9: Nashville | K9: Activo | L9: 45658 | M9: 45717 | N9: Perfecto | P9: Send
A10: 009 | B10: 615-830-6700 | C10: AT&T | D10: Iphone | E10: Iphone 11 Pro | F10: 353247104496222 | G10: QUIJANO, NICOLAS | H10: CFO | I10: Primera | J10: Nashville | K10: Activo | L10: 45658 | M10: 45717 | N10: Perfecto | P10: Send
A11: 010 | B11: 615-626-4243 | C11: AT&T | D11: Iphone | E11: iPhone 13 Pro Max A2484 128GB Graphite | F11: 350019045940745 | G11: HERRERA MOLINA, JOSE CARLOS | H11: CEO | I11: Primera | J11: Nashville | K11: Activo | L11: 45658 | M11: 45717 | N11: Perfecto | P11: Send
A12: 011 | B12: 615-626-7710 | C12: VERIZON | D12: Ipad | E12: 10.2 IPAD 8 GEN 32GB SG | F12: 356747116811213 | G12: HERRERA MOLINA, JOSE CARLOS | H12: CEO | I12: Primera | J12: Nashville | K12: Activo | L12: 45658 | M12: 45717 | N12: Perfecto | P12: Send
A13: 012 | B13: 615-316-8577 | C13: AT&T | D13: Iphone | E13: iPhone 14 Plus A2632 128GB Midnight | F13: 353547798360296 | G13: DUQUE IYENGAR, DANIELA | H13: HR | I13: Primera | J13: Nashville | K13: Activo | L13: 45658 | M13: 45717 | N13: Perfecto | P13: Send
A14: 013 | B14: 615-971-0833 | C14: VERIZON | D14: Galaxy | E14: SAMSUNG GALAXY A23 5G UW | F14: 355978840919284 | G14: BEARD, JUSTIN O | H14: LOGISTICS WEST | I14: Tercera | J14: Memphis | K14: Activo | L14: 45658 | M14: 45717 | N14: Perfecto
A15: 014 | B15: 615-337-4949 | C15: AT&T | D15: Galaxy | E15: SAMSUNG GALAXY A23 5G UW | F15: 351700860699123 | G15: CONDE TORRES, DAVID A | H15: WAREHOUSE CENTRAL | I15: Tercera | J15: Nashville | K15: Activo | L15: 45658 | M15: 45717 | N15: Perfecto
A16: 015 | B16: 901-607-5291 | C16: AT&T | D16: Galaxy | E16: SAMSUNG GALAXY A23 5G UW | F16: 355978840897134 | G16: CORPUS, BENY A | H16: LOGISTICS CENTRAL | I16: Tercera | J16: Nashville | K16: Activo | L16: 45658 | M16: 45717 | N16: Perfecto
A17: 244 | B17: 615-390-4624 | C17: AT&T | D17: Iphone | E17: Iphone 14 Pro MaX | F17: 356485673725928 | G17: ESQUIVEL, HENRY | H17: WAREHOUSE CENTRAL | I17: Segunda | J17: Nashville | K17: Activo | L17: 45658 | M17: 45717 | N17: Perfecto
A18: 017 | B18: 615-299-3641 | C18: AT&T | D18: Motorola | E18: moto g stylus 5G XT2131-3 128GB Cosmic Emerald | F18: 355984450930637 | G18: FERNANDEZ, EDGAR | H18: LOGISTICS CENTRAL | I18: Tercera | J18: Nashville | K18: Activo | L18: 45658 | M18: 45717 | N18: Perfecto
A19: 018 | B19: 629-239-0377 | C19: AT&T | D19: Iphone | E19: iPhone 13 A2482 128GB Midnight | F19: 358091652355105 | G19: LONGA, CARMEN B | H19: LOGISTICS WEST | I19: Segunda | J19: Memphis | K19: Activo | L19: 45658 | M19: 45717 | N19: Perfecto
A20: 019 | B20: 502-558-5770 | C20: AT&T | D20: Galaxy | E20: SAMSUNG GALAXY A23 5G UW | F20: 355978840941007 | G20: MOJICA, FRANCISCO JAVIER | H20: LOGISTICS CENTRAL | I20: Tercera | J20: Nashville | K20: Activo | L20: 45658 | M20: 45717 | N20: Perfecto
A21: 020 | B21: 615-862-9402 | C21: AT&T | D21: Galaxy | E21: Galaxy A13 5G SM-A136U 64GB Black | F21: 351082120997815 | G21: BAHENA, RUDY | H21: LOGISTICS WEST | I21: Tercera | J21: Memphis | K21: Activo | L21: 45658 | M21: 45717 | N21: Perfecto
A22: 021 | B22: 629-201-9859 | C22: VERIZON | D22: Galaxy | E22: SAMSUNG GALAXY A23 5G UW | F22: 355978840948754 | G22: LAMA, DENIS | H22: LOGISTICS NORTH | I22: Tercera | J22: Cincinnatti | K22: Activo | L22: 45658 | M22: 45717 | N22: Perfecto
A23: 022 | B23: 901-585-9984 | C23: AT&T | D23: Galaxy | E23: SAMSUNG GALAXY A23 5G UW | F23: 355978840945446 | G23: DE LA TORRE, LUIS G | H23: LOGISTICS WEST | I23: Tercera | J23: Memphis | K23: Activo | L23: 45658 | M23: 45717 | N23: Perfecto
A24: 023 | B24: 615-598-2524 | C24: VERIZON | D24: Galaxy | E24: SAMSUNG GALAXY A23 5G UW | F24: 355978840949059 | G24: SALGUERO, RONALD | H24: LOGISTIC SOUTH | I24: Tercera | J24: Birmingham | K24: Activo | L24: 45762 | M24: 45762 | N24: Perfecto
A25: 024 | B25: 615-795-8193 | C25: AT&T | D25: Galaxy | E25: SAMSUNG GALAXY A13 | F25: 351082120939429 | G25: REMBERT, ANTORIUS DAVUN | H25: LOGISTICS SOUTH | I25: Tercera | J25: Birmingham | K25: Activo | L25: 45658 | M25: 45717 | N25: Perfecto
A26: 025 | B26: 502-974-3915 | C26: AT&T | D26: Iphone | E26: IPHONE13 128GB MDN NVZ ATT | F26: 358091652696490 | G26: ARMES, CLAUDIA | H26: SALES NORTH | I26: Tercera | J26: Cincinnatti | K26: Activo | L26: 45658 | M26: 45717 | N26: Perfecto
A27: 026 | B27: 615-417-0015 | C27: AT&T | D27: Iphone | E27: iPhone 13 A2482 128GB Midnight | F27: 354739183440614 | G27: BARAJAS, JESSICA | H27: SALES NORTH | I27: Tercera | J27: Cincinnatti | K27: Activo | L27: 45658 | M27: 45717 | N27: Perfecto
A28: 027 | B28: 615-417-2841 | C28: VERIZON | D28: Ipad | E28: 10.2 IPAD 8 GEN 32GB SG | F28: 356749110441328 | G28: BARAJAS, JESSICA | H28: SALES NORTH | I28: Tercera | J28: Cincinnatti | K28: Activo | L28: 45658 | M28: 45717 | N28: Perfecto
A29: 028 | B29: 615-456-2536 | C29: AT&T | D29: Iphone | E29: IPHONE13 128GB MDN NVZ ATT | F29: 358091652064830 | G29: CABANZO, DANNY | H29: SALES CENTRAL | I29: Tercera | J29: Nashville | K29: Activo | L29: 45658 | M29: 45717 | N29: Perfecto
... A54: 053 | B54: 317-500-7156 | C54: AT&T | D54: Iphone | E54: IPHONE13 128GB MDN NVZ ATT | F54: 358091652408037 | G54: SORIANO, NAYELY | H54: SALES NORTH | I54: Tercera | J54: Cincinnatti | K54: Activo | L54: 45658 | M54: 45717 | N54: Perfecto
A55: 054 | B55: 615-881-2222 | C55: VERIZON | D55: Ipad | E55: IPAD 9GEN 64 GRAY | F55: 355254195678622 | G55: SORIANO, NAYELY | H55: SALES NORTH | I55: Tercera | J55: Cincinnatti | K55: DESCONECTADA | L55: 45658 | M55: 45717 | N55: Perfecto | O55: DESCONECTADA Y PASADA A ATT
A56: 055 | B56: 615-945-4365 | C56: AT&T | D56: Ipad | E56: iPad 9th Gen. (2021) A2603 64GB Space Gray | F56: 359552545614718 | G56: TELLO, IVAN E | H56: SALES CENTRAL | I56: Tercera | J56: Nashville | K56: Activo | L56: 45658 | M56: 45717 | N56: Perfecto
A57: 056 | B57: 615-730-3104 | C57: AT&T | D57: Iphone | E57: iPhone 14 Plus A2632 128GB Midnight | F57: 353547795738981 | G57: TELLO, IVAN E | H57: SALES CENTRAL | I57: Tercera | J57: Nashville | K57: Activo | L57: 45658 | M57: 45717 | N57: Perfecto
A58: 057 | B58: 615-812-1894 | C58: VERIZON | D58: Ipad | E58: IPAD 9GEN 64 GRAY | F58: 357883402867509 | G58: TORREALBA TORRES, CAROLINA | H58: SALES WEST | I58: Tercera | J58: Memphis | K58: DESCONECTADA | L58: 45658 | M58: 45717 | N58: Perfecto
A59: 058 | B59: 615-854-5797 | C59: AT&T | D59: Iphone | E59: IPHONE13 128GB MDN NVZ ATT | F59: 350980291513736 | G59: TORREALBA TORRES, CAROLINA | H59: SALES WEST | I59: Tercera | J59: Memphis | K59: Activo | L59: 45658 | M59: 45717 | N59: Perfecto
A60: 059 | B60: 615-878-0405 | C60: AT&T | G60: TORRES, LUIS | H60: MERCHANDISER NORTH | I60: Tercera | J60: Cincinnatti | O60: Asignar o ver si tien asignado
A61: 060 | B61: 615-714-1323 | C61: VERIZON | D61: Ipad | E61: IPAD 9GEN 64 GRAY | F61: 357652533500689 | G61: TOVAR, ZULLYMAR | H61: SALES CENTRAL | I61: Segunda | J61: Nashville | K61: Activo | L61: 45658 | M61: 45717 | N61: Perfecto
A62: 061 | B62: 865-396-3528 | C62: AT&T | D62: Ipad | E62: iPad 9th Gen. (2021) A2603 64GB Space Gray | F62: 359552541604085 | G62: VELIZ, CARLOS A | H62: SALES CENTRAL | I62: Tercera | J62: Nashville | K62: Activo | L62: 45658 | M62: 45717 | N62: Perfecto
A63: 062 | B63: 629-345-1182 | C63: AT&T | D63: Ipad | E63: iPad 9th Gen. (2021) A2603 64GB Space Gray | F63: 357652530925137 | G63: LACRUZ, ROSMARY | H63: SALES WEST | I63: Tercera | J63: Memphis | K63: Activo | L63: 45658 | M63: 45717 | N63: Perfecto
A64: 063 | B64: 601-910-8492 | C64: AT&T | D64: Iphone | E64: IPHONE12 64G BLK-E NVZ ATT | F64: 351139862096055 | G64: LACRUZ, ROSMARY | H64: SALES WEST | I64: Tercera | J64: Memphis | K64: Activo | L64: 45658 | M64: 45717 | N64: Perfecto
...

Sheet MIGRACION SEPTIEMBRE 2025
A1: ID | B1: LINEA MOVIL | C1: Proveedor | D1: EQUIPMENT TYPE | E1: MODEL | F1: IMEI | G1: Usuario Asignado | H1: CECO | I1: LINEA | J1: LOCATION | K1: Estado | L1: Fecha de asignacion | M1: Fecha de ultima revision | N1: Condicion de equipo | O1: Comentarios | P1: etf | Q1: TRANSFERENCIA DE PIN
A2: 001 | B2: 615-708-0397 | C2: AT&T | D2: Iphone | E2: A2849 256GB Black Titanium | F2: 356964995021992 | G2: MADRIZ, JOHAN | H2: President | I2: Primera | J2: Nashville | K2: Activo | L2: 45658 | M2: 45717 | N2: Perfecto
A3: 002 | B3: 615-477-6490 | C3: AT&T | D3: Iphone | E3: A2848 256GB White Titanium | F3: 352917261435522 | G3: VILLATORO, MERARI | H3: VP | I3: Primera | J3: Nashville | K3: Activo | L3: 45658 | M3: 45717 | N3: Perfecto
A4: 003
A5: 004
A6: 005 | B6: 615-496-8278 | C6: AT&T | D6: Iphone | E6: iphone 16 PRO Max 512 GB Black Titanium | F6: 357205981304151 | G6: MADRIZ, JOHAN | H6: President | I6: Primera | J6: Nashville | K6: Activo | L6: 45658 | M6: 45717 | N6: Perfecto
A7: 006 | B7: 615-403-8760 | C7: AT&T | D7: Iphone | E7: iPhone 13 Pro Max A2484 256GB Alpine Green | F7: 356985725478830 | G7: VILLATORO, MERARI | H7: VP | I7: Primera | J7: Nashville | K7: Activo | L7: 45658 | M7: 45717 | N7: Perfecto
A8: 007 | B8: 615-417-9594 | C8: AT&T | D8: Iphone | E8: iPhone 13 Pro Max A2484 256GB Graphite | F8: 350566101441174 | G8: QUIJANO, NICOLAS | H8: CFO | I8: Primera | J8: Nashville | K8: Activo | L8: 45658 | M8: 45717 | N8: Perfecto | P8: Send
A9: 008 | B9: 615-691-3166 | C9: AT&T | D9: Iphone | E9: iPhone 13 Pro Max A2484 256GB Gold | F9: 356796480675498 | G9: QUIJANO, NICOLAS | H9: CFO | I9: Primera | J9: Nashville | K9: Activo | L9: 45658 | M9: 45717 | N9: Perfecto | P9: Send
A10: 009 | B10: 615-830-6700 | C10: AT&T | D10: Iphone | E10: Iphone 11 Pro | F10: 353247104496222 | G10: QUIJANO, NICOLAS | H10: CFO | I10: Primera | J10: Nashville | K10: Activo | L10: 45658 | M10: 45717 | N10: Perfecto | P10: Send
A11: 010 | B11: 615-626-4243 | C11: AT&T | D11: Iphone | E11: iPhone 13 Pro Max A2484 128GB Graphite | F11: 350019045940745 | G11: HERRERA MOLINA, JOSE CARLOS | H11: CEO | I11: Primera | J11: Nashville | K11: Activo | L11: 45658 | M11: 45717 | N11: Perfecto | P11: Send
A12: 011 | B12: 615-626-7710 | C12: VERIZON | D12: Ipad | E12: 10.2 IPAD 8 GEN 32GB SG | F12: 356747116811213 | G12: HERRERA MOLINA, JOSE CARLOS | H12: CEO | I12: Primera | J12: Nashville | K12: Activo | L12: 45658 | M12: 45717 | N12: Perfecto | O12: REVISADO SEPT 15 | P12: 0 | Q12: yes
A13: 012 | B13: 615-316-8577 | C13: AT&T | D13: Iphone | E13: iPhone 14 Plus A2632 128GB Midnight | F13: 353547798360296 | G13: DUQUE IYENGAR, DANIELA | H13: HR | I13: Primera | J13: Nashville | K13: Activo | L13: 45658 | M13: 45717 | N13: Perfecto | P13: Send
A14: 013 | B14: 615-971-0833 | C14: VERIZON | D14: Galaxy | E14: SAMSUNG GALAXY A23 5G UW | F14: 355978840919284 | G14: BEARD, JUSTIN O | H14: LOGISTICS WEST | I14: Tercera | J14: Memphis | K14: Activo | L14: 45658 | M14: 45717 | N14: Perfecto
A15: 014 | B15: 615-337-4949 | C15: AT&T | D15: Galaxy | E15: SAMSUNG GALAXY A23 5G UW | F15: 351700860699123 | G15: CONDE TORRES, DAVID A | H15: WAREHOUSE CENTRAL | I15: Tercera | J15: Nashville | K15: Activo | L15: 45658 | M15: 45717 | N15: Perfecto
A16: 015 | B16: 901-607-5291 | C16: AT&T | D16: Galaxy | E16: SAMSUNG GALAXY A23 5G UW | F16: 355978840897134 | G16: CORPUS, BENY A | H16: LOGISTICS CENTRAL | I16: Tercera | J16: Nashville | K16: Activo | L16: 45658 | M16: 45717 | N16: Perfecto
A17: 244 | B17: 615-390-4624 | C17: AT&T | D17: Iphone | E17: Iphone 14 Pro MaX | F17: 356485673725928 | G17: ESQUIVEL, HENRY | H17: WAREHOUSE CENTRAL | I17: Segunda | J17: Nashville | K17: Activo | L17: 45658 | M17: 45717 | N17: Perfecto
A18: 017 | B18: 615-299-3641 | C18: AT&T | D18: Motorola | E18: moto g stylus 5G XT2131-3 128GB Cosmic Emerald | F18: 355984450930637 | G18: FERNANDEZ, EDGAR | H18: LOGISTICS CENTRAL | I18: Tercera | J18: Nashville | K18: Activo | L18: 45658 | M18: 45717 | N18: Perfecto
A19: 018 | B19: 629-239-0377 | C19: AT&T | D19: Iphone | E19: iPhone 13 A2482 128GB Midnight | F19: 358091652355105 | G19: LONGA, CARMEN B | H19: LOGISTICS WEST | I19: Segunda | J19: Memphis | K19: Activo | L19: 45658 | M19: 45717 | N19: Perfecto
A20: 019 | B20: 502-558-5770 | C20: AT&T | D20: Galaxy | E20: SAMSUNG GALAXY A23 5G UW | F20: 355978840941007 | G20: MOJICA, FRANCISCO JAVIER | H20: LOGISTICS CENTRAL | I20: Tercera | J20: Nashville | K20: Activo | L20: 45658 | M20: 45717 | N20: Perfecto
A21: 020 | B21: 615-862-9402 | C21: AT&T | D21: Galaxy | E21: Galaxy A13 5G SM-A136U 64GB Black | F21: 351082120997815 | G21: BAHENA, RUDY | H21: LOGISTICS WEST | I21: Tercera | J21: Memphis | K21: Activo | L21: 45658 | M21: 45717 | N21: Perfecto
A22: 021 | B22: 629-201-9859 | C22: VERIZON | D22: Galaxy | E22: SAMSUNG GALAXY A23 5G UW | F22: 355978840948754 | G22: LAMA, DENIS | H22: LOGISTICS NORTH | I22: Tercera | J22: Cincinnatti | K22: Activo | L22: 45658 | M22: 45717 | N22: Perfecto
A23: 022 | B23: 901-585-9984 | C23: AT&T | D23: Galaxy | E23: SAMSUNG GALAXY A23 5G UW | F23: 355978840945446 | G23: DE LA TORRE, LUIS G | H23: LOGISTICS WEST | I23: Tercera | J23: Memphis | K23: Activo | L23: 45658 | M23: 45717 | N23: Perfecto
A24: 023 | B24: 615-598-2524 | C24: VERIZON | D24: Galaxy | E24: SAMSUNG GALAXY A23 5G UW | F24: 355978840949059 | G24: SALGUERO, RONALD | H24: LOGISTIC SOUTH | I24: Tercera | J24: Birmingham | K24: Activo | L24: 45762 | M24: 45762 | N24: Perfecto | P24: 0 | Q24: yes | S24: CAMBIAR NOMBRE VERIZON
A25: 024 | B25: 615-795-8193 | C25: AT&T | D25: Galaxy | E25: SAMSUNG GALAXY A13 | F25: 351082120939429 | G25: REMBERT, ANTORIUS DAVUN | H25: LOGISTICS SOUTH | I25: Tercera | J25: Birmingham | K25: Activo | L25: 45658 | M25: 45717 | N25: Perfecto
A26: 025 | B26: 502-974-3915 | C26: AT&T | D26: Iphone | E26: IPHONE13 128GB MDN NVZ ATT | F26: 358091652696490 | G26: ARMES, CLAUDIA | H26: SALES NORTH | I26: Tercera | J26: Cincinnatti | K26: Activo | L26: 45658 | M26: 45717 | N26: Perfecto
A27: 026 | B27: 615-417-0015 | C27: AT&T | D27: Iphone | E27: iPhone 13 A2482 128GB Midnight | F27: 354739183440614 | G27: BARAJAS, JESSICA | H27: SALES NORTH | I27: Tercera | J27: Cincinnatti | K27: Activo | L27: 45658 | M27: 45717 | N27: Perfecto
A28: 027 | B28: 615-417-2841 | C28: VERIZON | D28: Ipad | E28: 10.2 IPAD 8 GEN 32GB SG | F28: 356749110441328 | G28: BARAJAS, JESSICA | H28: SALES NORTH | I28: Tercera | J28: Cincinnatti | K28: Activo | L28: 45658 | M28: 45717 | N28: Perfecto | P28: 0 | Q28: yes
A29: 028 | B29: 615-456-2536 | C29: AT&T | D29: Iphone | E29: IPHONE13 128GB MDN NVZ ATT | F29: 358091652064830 | G29: CABANZO, DANNY | H29: SALES CENTRAL | I29: Tercera | J29: Nashville | K29: Activo | L29: 45658 | M29: 45717 | N29: Perfecto
A30: 029 | B30: 615-840-1465 | C30: VERIZON | D30: Ipad | E30: 10.2 IPAD 8 GEN 32GB SG | F30: 356747112510629 | G30: CABANZO, DANNY | H30: SALES CENTRAL | I30: Tercera | J30: Nashville | K30: Activo | L30: 45658 | M30: 45717 | N30: Perfecto
A31: 030 | B31: 314-580-3315 | C31: AT&T | D31: Iphone | E31: IPHONE13 128GB MDN NVZ ATT | F31: 358091652243426 | G31: CAICEDO, VICTOR M | H31: SALES WEST | I31: Tercera | J31: Memphis | K31: Activo | L31: 45658 | M31: 45717 | N31: Perfecto
A32: 031 | B32: 615-840-3639 | C32: VERIZON | D32: Ipad | E32: IP 10.9 64 SLV 22 | F32: 355939971952932 | G32: CAICEDO, VICTOR M | H32: SALES WEST | I32: Tercera | J32: Memphis | K32: Activo | L32: 45658 | M32: 45717 | N32: Perfecto | O32: REVISADO SEPT 15 | P32: 0 | Q32: yes | R32: REVISAR QUIEN LO TIENE
A33: 032 | B33: 629-729-3287 | C33: AT&T | D33: Ipad | E33: iPad 9th Gen. (2021) A2603 64GB Space Gray | F33: 357652533185275 | G33: CHANCHAMIRE, RAFAEL A | H33: SALES WEST | I33: Tercera | J33: Memphis | K33: Activo | L33: 45658 | M33: 45717 | N33: Perfecto
A34: 033 | B34: 901-649-5850 | C34: AT&T | D34: Iphone | E34: iPhone 14 A2649 128GB Midnight | F34: 354633859827800 | G34: CHANCHAMIRE, RAFAEL A | H34: SALES WEST | I34: Tercera | J34: Memphis | K34: Activo | L34: 45658 | M34: 45717 | N34: Perfecto
A35: 034 | B35: 513-675-0865 | C35: AT&T | D35: Iphone | E35: IPHONE13 128GB MDN NVZ ATT | F35: 350555043090645 | G35: CORDERO, IRIS | H35: SALES NORTH | I35: Tercera | J35: Cincinnatti | K35: Activo | L35: 45658 | M35: 45717 | N35: Perfecto
A36: 035 | B36: 615-648-0861 | C36: VERIZON | D36: Ipad | E36: IPAD WIFI 32GB GOLD | F36: 359455081195458 | G36: CORDERO, IRIS | H36: SALES NORTH | I36: Tercera | J36: Cincinnatti | K36: Activo | L36: 45658 | M36: 45717 | N36: Perfecto | P36: 0 | Q36: yes
A37: 036 | B37: 256-631-4188 | C37: AT&T | D37: Ipad | E37: iPad 9th Gen. (2021) A2603 64GB Space Gray | F37: 351036279350523 | G37: FLORES, JOSE DANIEL | H37: SALES SOUTH | I37: Tercera | J37: Birmingham | K37: Activo | L37: 45658 | M37: 45717 | N37: Perfecto
A38: 037 | B38: 256-724-1530 | C38: AT&T | D38: Iphone | E38: iPhone 13 A2482 128GB Midnight | F38: 359346671900953 | G38: FLORES, JOSE DANIEL | H38: SALES SOUTH | I38: Tercera | J38: Birmingham | K38: Activo | L38: 45658 | M38: 45717 | N38: Perfecto
A39: 038 | B39: 205-767-8090 | C39: AT&T | D39: Iphone | E39: IPHONE13 128GB MDN NVZ ATT | F39: 358469523459878 | G39: GUERRERO, JESUS | H39: SALES SOUTH | I39: Segunda | J39: Birmingham | K39: Activo | L39: 45658 | M39: 45717 | N39: Perfecto
A40: 039 | B40: 615-840-1479 | C40: VERIZON | D40: Ipad | E40: IPAD 9.7 128GB SILVER VZ | F40: 353036091434008 | G40: GUERRERO, JESUS | H40: SALES SOUTH | I40: Segunda | J40: Birmingham | K40: Activo | L40: 45658 | M40: 45717 | N40: Perfecto
...

Sheet Sheet5
A1: LINEA MOVIL | B1: Proveedor | C1: EQUIPMENT TYPE | D1: MODEL | E1: IMEI | F1: Usuario Asignado | G1: CECO | H1: LINEA | I1: LOCATION | J1: Estado | K1: Fecha de asignacion | L1: Fecha de ultima revision | M1: Condicion de equipo | N1: Comentarios | O1: etf | P1: TRANSFERENCIA DE PIN | S1: Migracion
A2: 615-626-7710 | B2: VERIZON | C2: Ipad | D2: 10.2 IPAD 8 GEN 32GB SG | E2: 356747116811213 | F2: HERRERA MOLINA, JOSE CARLOS | G2: CEO | H2: Primera | I2: Nashville | J2: Activo | K2: 45658 | L2: 45717 | M2: Perfecto | N2: REVISADO SEPT 15 | O2: 0 | P2: yes
A3: 615-971-0833 | B3: VERIZON | C3: Galaxy | D3: SAMSUNG GALAXY A23 5G UW | E3: 355978840919284 | F3: BEARD, JUSTIN O | G3: LOGISTICS WEST | H3: Tercera | I3: Memphis | J3: Activo | K3: 45658 | L3: 45717 | M3: Perfecto
A4: 629-201-9859 | B4: VERIZON | C4: Galaxy | D4: SAMSUNG GALAXY A23 5G UW | E4: 355978840948754 | F4: LAMA, DENIS | G4: LOGISTICS NORTH | H4: Tercera | I4: Cincinnatti | J4: Activo | K4: 45658 | L4: 45717 | M4: Perfecto
A5: 615-598-2524 | B5: VERIZON | C5: Galaxy | D5: SAMSUNG GALAXY A23 5G UW | E5: 355978840949059 | F5: SALGUERO, RONALD | G5: LOGISTIC SOUTH | H5: Tercera | I5: Birmingham | J5: Activo | K5: 45762 | L5: 45762 | M5: Perfecto | O5: 0 | P5: yes | R5: CAMBIAR NOMBRE VERIZON
A6: 615-417-2841 | B6: VERIZON | C6: Ipad | D6: 10.2 IPAD 8 GEN 32GB SG | E6: 356749110441328 | F6: BARAJAS, JESSICA | G6: SALES NORTH | H6: Tercera | I6: Cincinnatti | J6: Activo | K6: 45658 | L6: 45717 | M6: Perfecto | O6: 0 | P6: yes
A7: 615-840-1465 | B7: VERIZON | C7: Ipad | D7: 10.2 IPAD 8 GEN 32GB SG | E7: 356747112510629 | F7: CABANZO, DANNY | G7: SALES CENTRAL | H7: Tercera | I7: Nashville | J7: Activo | K7: 45658 | L7: 45717 | M7: Perfecto
A8: 615-648-0861 | B8: VERIZON | C8: Ipad | D8: IPAD WIFI 32GB GOLD | E8: 359455081195458 | F8: CORDERO, IRIS | G8: SALES NORTH | H8: Tercera | I8: Cincinnatti | J8: Activo | K8: 45658 | L8: 45717 | M8: Perfecto | O8: 0 | P8: yes
A9: 615-840-1479 | B9: VERIZON | C9: Ipad | D9: IPAD 9.7 128GB SILVER VZ | E9: 353036091434008 | F9: GUERRERO, JESUS | G9: SALES SOUTH | H9: Segunda | I9: Birmingham | J9: Activo | K9: 45658 | L9: 45717 | M9: Perfecto
A10: 615-806-3926 | B10: VERIZON | C10: Ipad | D10: 10.2 IPAD 8 GEN 32GB SG | E10: 356747116798246 | F10: REYES, YULIN | G10: SALES CENTRAL | H10: Tercera | I10: Nashville | J10: Activo | K10: 45658 | L10: 45717 | M10: Perfecto | O10: 0 | P10: YES
A11: 615-812-4735 | B11: VERIZON | C11: Ipad | D11: 10.2 IPAD 8 GEN 32GB SG | E11: 356747116975323 | F11: ROA, INGRID MARCELA | G11: SALES SOUTH | H11: Tercera | I11: Birmingham | J11: Activo | K11: 45658 | L11: 45717 | M11: Perfecto
